Workbook

Sheet Tomatillo
F2: TOTAL | G2: =SUM(G4:G495) -> 5893 | H2: =SUM(H4:H495) -> 5893 | I2: =SUM(I4:I495) -> 0 | J2: =SUM(J4:J495) -> 0 | K2: =R2/H2 -> 163.62276 | L2: =O2/(G2*17) -> 10.55029 | M2: =SUM(M4:M495) -> 1061338.6 | N2: =SUM(N4:N495) -> 4400 | O2: =SUM(O4:O495) -> 1056938.6 | P2: =Q2/O2 -> 0.087715282 | Q2: =SUM(Q4:Q495) -> 92709.664 | R2: =SUM(R4:R495) -> 964228.9 | S2: =SUM(S4:S495) -> 0 | T2: =SUM(T4:T495) -> 964228.9
B3: Fecha | C3: Manifiesto | D3: Agricultor | E3: Cliente | F3: Producto | G3: Enviadas | H3: Reportadas | I3: Merma | J3: x reportar | K3: Precio | L3: $ KG | M3: Venta | N3: Gastos | O3: Subtotal | P3: Comisión | Q3: Comisión CBE | R3: Total | S3: Estimado | T3: Real + Est
B4: 46128 | C4: 1 | D4: H2E | E4: Carlos Perez | F4: Tomatillo | G4: 50 | H4: 50 | J4: =G4-H4-I4 -> 0 | K4: 306 | L4: =O4/H4/17 -> 18 | M4: =K4*H4 -> 15300 | N4: 0 | O4: =IF(H4="",0,M4-N4) -> 15300 | P4: 0.1 | Q4: =O4*P4 -> 1530 | R4: =IF(J4=0,O4-Q4,0) -> 13770 | S4: =IF(J4=0,0,(J4*K4)-N4-(J4*K4-N4)*P4) -> 0 | T4: =R4+S4 -> 13770
B5: 46128 | C5: 2 | D5: H2E | E5: Carlos Perez | F5: Tomatillo | G5: 10 | H5: 10 | J5: =G5-H5-I5 -> 0 | K5: 306 | L5: =K5/17 -> 18 | M5: =K5*H5 -> 3060 | N5: 0 | O5: =IF(H5="",0,M5-N5) -> 3060 | P5: 0.1 | Q5: =O5*P5 -> 306 | R5: =IF(J5=0,O5-Q5,0) -> 2754 | S5: =IF(J5=0,0,(J5*K5)-N5-(J5*K5-N5)*P5) -> 0 | T5: =R5+S5 -> 2754
B6: 46128 | C6: 3 | D6: H2E | E6: Mayojoa | F6: Tomatillo | G6: 20 | H6: 20 | J6: =G6-H6-I6 -> 0 | K6: 306 | L6: =K6/17 -> 18 | M6: =K6*H6 -> 6120 | N6: 0 | O6: =IF(H6="",0,M6-N6) -> 6120 | P6: 0.1 | Q6: =O6*P6 -> 612 | R6: =IF(J6=0,O6-Q6,0) -> 5508 | S6: =IF(J6=0,0,(J6*K6)-N6-(J6*K6-N6)*P6) -> 0 | T6: =R6+S6 -> 5508
B7: 46128 | C7: 4 | D7: H2E | E7: Luis Carlos Cejudo | F7: Tomatillo | G7: 48 | H7: 48 | J7: =G7-H7-I7 -> 0 | K7: =15*17 -> 255 | L7: =K7/17 -> 15 | M7: =K7*H7 -> 12240 | N7: 0 | O7: =IF(H7="",0,M7-N7) -> 12240 | P7: 0.1 | Q7: =O7*P7 -> 1224 | R7: =IF(J7=0,O7-Q7,0) -> 11016 | S7: =IF(J7=0,0,(J7*K7)-N7-(J7*K7-N7)*P7) -> 0 | T7: =R7+S7 -> 11016
B8: 46128 | C8: 5 | D8: H2E | E8: Bodega Lizarraga | F8: Tomatillo | G8: =8*48 -> 384 | H8: 384 | J8: =G8-H8-I8 -> 0 | K8: =17*17 -> 289 | L8: =K8/17 -> 17 | M8: =K8*H8 -> 110976 | N8: 0 | O8: =IF(H8="",0,M8-N8) -> 110976 | P8: 0.1 | Q8: =O8*P8 -> 11097.6 | R8: =IF(J8=0,O8-Q8,0) -> 99878.4 | S8: =IF(J8=0,0,(J8*K8)-N8-(J8*K8-N8)*P8) -> 0 | T8: =R8+S8 -> 99878.4
B9: 46129 | C9: 7 | D9: H2E | E9: Mayojoa | F9: Tomatillo | G9: 50 | H9: 50 | J9: =G9-H9-I9 -> 0 | K9: =18*17 -> 306 | L9: =K9/17 -> 18 | M9: =K9*H9 -> 15300 | N9: 0 | O9: =IF(H9="",0,M9-N9) -> 15300 | P9: 0.1 | Q9: =O9*P9 -> 1530 | R9: =IF(J9=0,O9-Q9,0) -> 13770 | S9: =IF(J9=0,0,(J9*K9)-N9-(J9*K9-N9)*P9) -> 0 | T9: =R9+S9 -> 13770
B10: 46129 | C10: 9 | D10: H2E | E10: Porfirio Casarez | F10: Tomatillo | G10: =6*48 -> 288 | H10: 288 | J10: =G10-H10-I10 -> 0 | K10: =13*17 -> 221 | L10: =K10/17 -> 13 | M10: =K10*H10 -> 63648 | N10: 0 | O10: =IF(H10="",0,M10-N10) -> 63648 | P10: 0.1 | Q10: =O10*P10 -> 6364.8 | R10: =IF(J10=0,O10-Q10,0) -> 57283.2 | S10: =IF(J10=0,0,(J10*K10)-N10-(J10*K10-N10)*P10) -> 0 | T10: =R10+S10 -> 57283.2
B11: 46129 | C11: 10 | D11: H2E | E11: Jorge Luis Zazueta | F11: Tomatillo | G11: 96 | H11: 96 | J11: =G11-H11-I11 -> 0 | K11: =13*17 -> 221 | L11: =K11/17 -> 13 | M11: =K11*H11 -> 21216 | N11: 4400 | O11: =IF(H11="",0,M11-N11) -> 16816 | P11: 0.1 | Q11: =O11*P11 -> 1681.6 | R11: =IF(J11=0,O11-Q11,0) -> 15134.4 | S11: =IF(J11=0,0,(J11*K11)-N11-(J11*K11-N11)*P11) -> 0 | T11: =R11+S11 -> 15134.4
B12: 46130 | C12: 11 | D12: H2E | E12: Carlos Perez | F12: Tomatillo | G12: =147 -> 147 | H12: 147 | J12: =G12-H12-I12 -> 0 | K12: =14*17 -> 238 | L12: =K12/17 -> 14 | M12: =K12*H12 -> 34986 | N12: 0 | O12: =IF(H12="",0,M12-N12) -> 34986 | P12: 0.1 | Q12: =O12*P12 -> 3498.6 | R12: =IF(J12=0,O12-Q12,0) -> 31487.4 | S12: =IF(J12=0,0,(J12*K12)-N12-(J12*K12-N12)*P12) -> 0 | T12: =R12+S12 -> 31487.4
B13: 46130 | C13: 12 | D13: H2E | E13: Ziracua | F13: Tomatillo | G13: 150 | H13: 150 | J13: =G13-H13-I13 -> 0 | K13: =17*17 -> 289 | L13: =K13/17 -> 17 | M13: =K13*H13 -> 43350 | N13: 0 | O13: =IF(H13="",0,M13-N13) -> 43350 | P13: 0.1 | Q13: =O13*P13 -> 4335 | R13: =IF(J13=0,O13-Q13,0) -> 39015 | S13: =IF(J13=0,0,(J13*K13)-N13-(J13*K13-N13)*P13) -> 0 | T13: =R13+S13 -> 39015
B14: 46132 | C14: 13 | D14: H2E | E14: Mayojoa | F14: Tomatillo | G14: 20 | H14: 20 | J14: =G14-H14-I14 -> 0 | K14: =15*17 -> 255 | L14: =K14/17 -> 15 | M14: =K14*H14 -> 5100 | N14: 0 | O14: =IF(H14="",0,M14-N14) -> 5100 | P14: 0.1 | Q14: =O14*P14 -> 510 | R14: =IF(J14=0,O14-Q14,0) -> 4590 | S14: =IF(J14=0,0,(J14*K14)-N14-(J14*K14-N14)*P14) -> 0 | T14: =R14+S14 -> 4590
B15: 46132 | C15: 14 | D15: H2E | E15: Efrén Medina | F15: Tomatillo | G15: 150 | H15: 150 | J15: =G15-H15-I15 -> 0 | K15: 255 | L15: =K15/17 -> 15 | M15: =K15*H15 -> 38250 | N15: 0 | O15: =IF(H15="",0,M15-N15) -> 38250 | P15: 0.1 | Q15: =O15*P15 -> 3825 | R15: =IF(J15=0,O15-Q15,0) -> 34425 | S15: =IF(J15=0,0,(J15*K15)-N15-(J15*K15-N15)*P15) -> 0 | T15: =R15+S15 -> 34425
B16: 46133 | C16: 16 | D16: H2E | E16: Ziracua | F16: Tomatillo | G16: 200 | H16: 200 | J16: =G16-H16-I16 -> 0 | K16: =16*17 -> 272 | L16: =K16/17 -> 16 | M16: =K16*H16 -> 54400 | N16: 0 | O16: =IF(H16="",0,M16-N16) -> 54400 | P16: 0.1 | Q16: =O16*P16 -> 5440 | R16: =IF(J16=0,O16-Q16,0) -> 48960 | S16: =IF(J16=0,0,(J16*K16)-N16-(J16*K16-N16)*P16) -> 0 | T16: =R16+S16 -> 48960
B17: 46133 | C17: 16 | D17: H2E | E17: Ziracua | F17: Tomatillo | G17: 3 | H17: 3 | J17: =G17-H17-I17 -> 0 | K17: 0 | L17: =K17/17 -> 0 | M17: =K17*H17 -> 0 | O17: =IF(H17="",0,M17-N17) -> 0 | Q17: =O17*P17 -> 0 | R17: =IF(J17=0,O17-Q17,0) -> 0 | S17: =IF(J17=0,0,(J17*K17)-N17-(J17*K17-N17)*P17) -> 0 | T17: =R17+S17 -> 0 | U17: Cajas por compensación de diferencia en peso
B18: 46134 | C18: 17 | D18: H2E | E18: Frutierrez | F18: Tomatillo | G18: 48 | H18: 48 | J18: =G18-H18-I18 -> 0 | K18: 255 | L18: =K18/17 -> 15 | M18: =K18*H18 -> 12240 | N18: 0 | O18: =IF(H18="",0,M18-N18) -> 12240 | P18: 0.1 | Q18: =O18*P18 -> 1224 | R18: =IF(J18=0,O18-Q18,0) -> 11016 | S18: =IF(J18=0,0,(J18*K18)-N18-(J18*K18-N18)*P18) -> 0 | T18: =R18+S18 -> 11016
B19: 46134 | C19: 18 | D19: H2E | E19: Porfirio Casarez | F19: Tomatillo | G19: 624 | H19: 624 | J19: =G19-H19-I19 -> 0 | K19: 136 | L19: =K19/17 -> 8 | M19: =K19*H19 -> 84864 | N19: 0 | O19: =IF(H19="",0,M19-N19) -> 84864 | P19: 0.1 | Q19: =O19*P19 -> 8486.4 | R19: =IF(J19=0,O19-Q19,0) -> 76377.6 | S19: =IF(J19=0,0,(J19*K19)-N19-(J19*K19-N19)*P19) -> 0 | T19: =R19+S19 -> 76377.6
B20: 46136 | C20: 20 | D20: H2E | E20: Carlos Perez | F20: Tomatillo | G20: 30 | H20: 30 | J20: =G20-H20-I20 -> 0 | K20: =12*17 -> 204 | L20: =K20/17 -> 12 | M20: =K20*H20 -> 6120 | N20: 0 | O20: =IF(H20="",0,M20-N20) -> 6120 | P20: 0.1 | Q20: =O20*P20 -> 612 | R20: =IF(J20=0,O20-Q20,0) -> 5508 | S20: =IF(J20=0,0,(J20*K20)-N20-(J20*K20-N20)*P20) -> 0 | T20: =R20+S20 -> 5508
B21: 46046 | C21: 21 | D21: H2E | E21: Porfirio Casarez | F21: Tomatillo | G21: 1209 | H21: 1209 | J21: =G21-H21-I21 -> 0 | K21: =10*17 -> 170 | L21: =K21/17 -> 10 | M21: =K21*H21 -> 205530 | N21: 0 | O21: =IF(H21="",0,M21-N21) -> 205530 | P21: 0.1 | Q21: =O21*P21 -> 20553 | R21: =IF(J21=0,O21-Q21,0) -> 184977 | S21: =IF(J21=0,0,(J21*K21)-N21-(J21*K21-N21)*P21) -> 0 | T21: =R21+S21 -> 184977
B22: 46137 | C22: 23 | D22: H2E | E22: Carlos Perez | F22: Tomatillo | G22: 30 | H22: 30 | J22: =G22-H22-I22 -> 0 | K22: =12*17 -> 204 | L22: =K22/17 -> 12 | M22: =K22*H22 -> 6120 | N22: 0 | O22: =IF(H22="",0,M22-N22) -> 6120 | P22: 0.1 | Q22: =O22*P22 -> 612 | R22: =IF(J22=0,O22-Q22,0) -> 5508 | S22: =IF(J22=0,0,(J22*K22)-N22-(J22*K22-N22)*P22) -> 0 | T22: =R22+S22 -> 5508
B23: 46142 | C23: 27 | D23: H2E | E23: Samuel Cuadras | F23: Tomatillo | G23: 21 | H23: 21 | J23: =G23-H23-I23 -> 0 | K23: =12*17 -> 204 | L23: =K23/17 -> 12 | M23: =K23*H23 -> 4284 | N23: 0 | O23: =IF(H23="",0,M23-N23) -> 4284 | P23: 0.1 | Q23: =O23*P23 -> 428.4 | R23: =IF(J23=0,O23-Q23,0) -> 3855.6 | S23: =IF(J23=0,0,(J23*K23)-N23-(J23*K23-N23)*P23) -> 0 | T23: =R23+S23 -> 3855.6
B24: 46142 | C24: 28 | D24: H2E | E24: Bodega Lizarraga | F24: Tomatillo | G24: =48*8 -> 384 | H24: 384 | J24: =G24-H24-I24 -> 0 | K24: 204 | L24: =K24/17 -> 12 | M24: =K24*H24 -> 78336 | N24: 0 | O24: =IF(H24="",0,M24-N24) -> 78336 | P24: 0.1 | Q24: =O24*P24 -> 7833.6 | R24: =IF(J24=0,O24-Q24,0) -> 70502.4 | S24: =IF(J24=0,0,(J24*K24)-N24-(J24*K24-N24)*P24) -> 0 | T24: =R24+S24 -> 70502.4
B25: 46143 | C25: 29 | D25: H2E | E25: Efrén Medina | F25: Tomatillo | G25: 80 | H25: 80 | J25: =G25-H25-I25 -> 0 | K25: =13*17 -> 221 | L25: =K25/17 -> 13 | M25: =K25*H25 -> 17680 | N25: 0 | O25: =IF(H25="",0,M25-N25) -> 17680 | P25: 0.1 | Q25: =O25*P25 -> 1768 | R25: =IF(J25=0,O25-Q25,0) -> 15912 | S25: =IF(J25=0,0,(J25*K25)-N25-(J25*K25-N25)*P25) -> 0 | T25: =R25+S25 -> 15912
B26: 46146 | C26: 32 | D26: H2E | E26: Porfirio Casarez | F26: Tomatillo | G26: 1248 | H26: 1248 | J26: =G26-H26-I26 -> 0 | K26: =6.12*17 -> 104.04 | L26: =K26/17 -> 6.12 | M26: =K26*H26 -> 129841.92 | N26: 0 | O26: =IF(H26="",0,M26-N26) -> 129841.92 | P26: 0 | Q26: =O26*P26 -> 0 | R26: =IF(J26=0,O26-Q26,0) -> 129841.92 | S26: =IF(J26=0,0,(J26*K26)-N26-(J26*K26-N26)*P26) -> 0 | T26: =R26+S26 -> 129841.92 | U26: $45 mil pesos de flete pagados por H2E
B27: 46147 | C27: 34 | D27: H2E | E27: Bodega Lizarraga | F27: Tomatillo | G27: 319 | H27: 319 | J27: =G27-H27-I27 -> 0 | K27: =17*11 -> 187 | L27: =K27/17 -> 11 | M27: =K27*H27 -> 59653 | N27: 0 | O27: =IF(H27="",0,M27-N27) -> 59653 | P27: 0.1 | Q27: =O27*P27 -> 5965.3 | R27: =IF(J27=0,O27-Q27,0) -> 53687.7 | S27: =IF(J27=0,0,(J27*K27)-N27-(J27*K27-N27)*P27) -> 0 | T27: =R27+S27 -> 53687.7
B28: 46149 | C28: 35 | D28: H2E | E28: Mayojoa | F28: Tomatillo | G28: 1 | H28: 1 | J28: =G28-H28-I28 -> 0 | K28: =17*8 -> 136 | L28: =K28/17 -> 8 | M28: =K28*H28 -> 136 | N28: 0 | O28: =IF(H28="",0,M28-N28) -> 136 | P28: 0.1 | Q28: =O28*P28 -> 13.6 | R28: =IF(J28=0,O28-Q28,0) -> 122.4 | S28: =IF(J28=0,0,(J28*K28)-N28-(J28*K28-N28)*P28) -> 0 | T28: =R28+S28 -> 122.4
B29: 46149 | C29: 36 | D29: H2E | E29: Mayojoa | F29: Tomatillo | G29: 59 | H29: 59 | J29: =G29-H29-I29 -> 0 | K29: =7*17 -> 119 | L29: =K29/17 -> 7 | M29: =K29*H29 -> 7021 | N29: 0 | O29: =IF(H29="",0,M29-N29) -> 7021 | P29: 0.1 | Q29: =O29*P29 -> 702.1 | R29: =IF(J29=0,O29-Q29,0) -> 6318.9 | S29: =IF(J29=0,0,(J29*K29)-N29-(J29*K29-N29)*P29) -> 0 | T29: =R29+S29 -> 6318.9
B30: 46150 | C30: 37 | D30: H2E | E30: Efrén Medina | F30: Tomatillo | G30: 120 | H30: 120 | J30: =G30-H30-I30 -> 0 | K30: 136 | L30: =K30/17 -> 8 | M30: =K30*H30 -> 16320 | N30: 0 | O30: =IF(H30="",0,M30-N30) -> 16320 | P30: 0.1 | Q30: =O30*P30 -> 1632 | R30: =IF(J30=0,O30-Q30,0) -> 14688 | S30: =IF(J30=0,0,(J30*K30)-N30-(J30*K30-N30)*P30) -> 0 | T30: =R30+S30 -> 14688
B31: 46154 | C31: 46 | D31: H2E | E31: Mayojoa | F31: Tomatillo | G31: 104 | H31: 104 | J31: =G31-H31-I31 -> 0 | K31: =5.23*17 -> 88.91 | L31: =K31/17 -> 5.23 | M31: =K31*H31 -> 9246.64 | N31: 0 | O31: =IF(H31="",0,M31-N31) -> 9246.64 | P31: 0.1 | Q31: =O31*P31 -> 924.664 | R31: =IF(J31=0,O31-Q31,0) -> 8321.976 | S31: =IF(J31=0,0,(J31*K31)-N31-(J31*K31-N31)*P31) -> 0 | T31: =R31+S31 -> 8321.976
J32: =G32-H32-I32 -> 0 | L32: =K32/17 -> 0 | M32: =K32*H32 -> 0 | O32: =IF(H32="",0,M32-N32) -> 0 | Q32: =O32*P32 -> 0 | R32: =IF(J32=0,O32-Q32,0) -> 0 | S32: =IF(J32=0,0,(J32*K32)-N32-(J32*K32-N32)*P32) -> 0 | T32: =R32+S32 -> 0
J33: =G33-H33-I33 -> 0 | L33: =K33/17 -> 0 | M33: =K33*H33 -> 0 | O33: =IF(H33="",0,M33-N33) -> 0 | Q33: =O33*P33 -> 0 | R33: =IF(J33=0,O33-Q33,0) -> 0 | S33: =IF(J33=0,0,(J33*K33)-N33-(J33*K33-N33)*P33) -> 0 | T33: =R33+S33 -> 0
J34: =G34-H34-I34 -> 0 | L34: =K34/17 -> 0 | M34: =K34*H34 -> 0 | O34: =IF(H34="",0,M34-N34) -> 0 | Q34: =O34*P34 -> 0 | R34: =IF(J34=0,O34-Q34,0) -> 0 | S34: =IF(J34=0,0,(J34*K34)-N34-(J34*K34-N34)*P34) -> 0 | T34: =R34+S34 -> 0
J35: =G35-H35-I35 -> 0 | L35: =K35/17 -> 0 | M35: =K35*H35 -> 0 | O35: =IF(H35="",0,M35-N35) -> 0 | Q35: =O35*P35 -> 0 | R35: =IF(J35=0,O35-Q35,0) -> 0 | S35: =IF(J35=0,0,(J35*K35)-N35-(J35*K35-N35)*P35) -> 0 | T35: =R35+S35 -> 0
J36: =G36-H36-I36 -> 0 | L36: =K36/17 -> 0 | M36: =K36*H36 -> 0 | O36: =IF(H36="",0,M36-N36) -> 0 | Q36: =O36*P36 -> 0 | R36: =IF(J36=0,O36-Q36,0) -> 0 | S36: =IF(J36=0,0,(J36*K36)-N36-(J36*K36-N36)*P36) -> 0 | T36: =R36+S36 -> 0
J37: =G37-H37-I37 -> 0 | L37: =K37/17 -> 0 | M37: =K37*H37 -> 0 | O37: =IF(H37="",0,M37-N37) -> 0 | Q37: =O37*P37 -> 0 | R37: =IF(J37=0,O37-Q37,0) -> 0 | S37: =IF(J37=0,0,(J37*K37)-N37-(J37*K37-N37)*P37) -> 0 | T37: =R37+S37 -> 0
J38: =G38-H38-I38 -> 0 | L38: =K38/17 -> 0 | M38: =K38*H38 -> 0 | O38: =IF(H38="",0,M38-N38) -> 0 | Q38: =O38*P38 -> 0 | R38: =IF(J38=0,O38-Q38,0) -> 0 | S38: =IF(J38=0,0,(J38*K38)-N38-(J38*K38-N38)*P38) -> 0 | T38: =R38+S38 -> 0
J39: =G39-H39-I39 -> 0 | L39: =K39/17 -> 0 | M39: =K39*H39 -> 0 | O39: =IF(H39="",0,M39-N39) -> 0 | Q39: =O39*P39 -> 0 | R39: =IF(J39=0,O39-Q39,0) -> 0 | S39: =IF(J39=0,0,(J39*K39)-N39-(J39*K39-N39)*P39) -> 0 | T39: =R39+S39 -> 0
J40: =G40-H40-I40 -> 0 | L40: =K40/17 -> 0 | M40: =K40*H40 -> 0 | O40: =IF(H40="",0,M40-N40) -> 0 | Q40: =O40*P40 -> 0 | R40: =IF(J40=0,O40-Q40,0) -> 0 | S40: =IF(J40=0,0,(J40*K40)-N40-(J40*K40-N40)*P40) -> 0 | T40: =R40+S40 -> 0
J41: =G41-H41-I41 -> 0 | L41: =K41/17 -> 0 | M41: =K41*H41 -> 0 | O41: =IF(H41="",0,M41-N41) -> 0 | Q41: =O41*P41 -> 0 | R41: =IF(J41=0,O41-Q41,0) -> 0 | S41: =IF(J41=0,0,(J41*K41)-N41-(J41*K41-N41)*P41) -> 0 | T41: =R41+S41 -> 0
...

Sheet Morrón
F2: TOTAL | G2: =SUM(G4:G494) -> 33 | H2: =SUM(H4:H494) -> 33 | I2: =SUM(I4:I494) -> 0 | J2: =SUM(J4:J494) -> 0 | K2: =R2/H2 -> 228.54545 | L2: =O2/(G2*17) -> 14.937611 | M2: =SUM(M4:M494) -> 8380 | N2: =SUM(N4:N494) -> 0 | O2: =SUM(O4:O494) -> 8380 | P2: =Q2/O2 -> 0.1 | Q2: =SUM(Q4:Q494) -> 838 | R2: =SUM(R4:R494) -> 7542 | S2: =SUM(S4:S494) -> 0 | T2: =SUM(T4:T494) -> 7542
B3: Fecha | C3: Manifiesto | D3: Agricultor | E3: Cliente | F3: Producto | G3: Enviadas | H3: Reportadas | I3: Merma | J3: x reportar | K3: Precio | L3: $ KG | M3: Venta | N3: Gastos | O3: Subtotal | P3: Comisión | Q3: Comisión CBE | R3: Total | S3: Estimado | T3: Real + Est
B4: 46139 | C4: 24 | D4: H2E | E4: Samuel Cuadras | F4: Morrón V | G4: 10 | H4: 10 | J4: =G4-H4-I4 -> 0 | K4: 240 | L4: =O4/H4/17 -> 14.117647 | M4: =K4*H4 -> 2400 | N4: 0 | O4: =IF(H4="",0,M4-N4) -> 2400 | P4: 0.1 | Q4: =O4*P4 -> 240 | R4: =IF(J4=0,O4-Q4,0) -> 2160 | S4: =IF(J4=0,0,(J4*K4)-N4-(J4*K4-N4)*P4) -> 0 | T4: =R4+S4 -> 2160
B5: 46151 | C5: 40 | D5: H2E | E5: Mayojoa | F5: Morrón V | G5: 23 | H5: 23 | J5: =G5-H5-I5 -> 0 | K5: 260 | L5: =K5/17 -> 15.294118 | M5: =K5*H5 -> 5980 | N5: 0 | O5: =IF(H5="",0,M5-N5) -> 5980 | P5: 0.1 | Q5: =O5*P5 -> 598 | R5: =IF(J5=0,O5-Q5,0) -> 5382 | S5: =IF(J5=0,0,(J5*K5)-N5-(J5*K5-N5)*P5) -> 0 | T5: =R5+S5 -> 5382
J6: =G6-H6-I6 -> 0 | L6: =K6/17 -> 0 | M6: =K6*H6 -> 0 | N6: 0 | O6: =IF(H6="",0,M6-N6) -> 0 | Q6: =O6*P6 -> 0 | R6: =IF(J6=0,O6-Q6,0) -> 0 | S6: =IF(J6=0,0,(J6*K6)-N6-(J6*K6-N6)*P6) -> 0 | T6: =R6+S6 -> 0
J7: =G7-H7-I7 -> 0 | L7: =K7/17 -> 0 | M7: =K7*H7 -> 0 | N7: 0 | O7: =IF(H7="",0,M7-N7) -> 0 | Q7: =O7*P7 -> 0 | R7: =IF(J7=0,O7-Q7,0) -> 0 | S7: =IF(J7=0,0,(J7*K7)-N7-(J7*K7-N7)*P7) -> 0 | T7: =R7+S7 -> 0
J8: =G8-H8-I8 -> 0 | L8: =K8/17 -> 0 | M8: =K8*H8 -> 0 | N8: 0 | O8: =IF(H8="",0,M8-N8) -> 0 | Q8: =O8*P8 -> 0 | R8: =IF(J8=0,O8-Q8,0) -> 0 | S8: =IF(J8=0,0,(J8*K8)-N8-(J8*K8-N8)*P8) -> 0 | T8: =R8+S8 -> 0
J9: =G9-H9-I9 -> 0 | L9: =K9/17 -> 0 | M9: =K9*H9 -> 0 | N9: 0 | O9: =IF(H9="",0,M9-N9) -> 0 | Q9: =O9*P9 -> 0 | R9: =IF(J9=0,O9-Q9,0) -> 0 | S9: =IF(J9=0,0,(J9*K9)-N9-(J9*K9-N9)*P9) -> 0 | T9: =R9+S9 -> 0
J10: =G10-H10-I10 -> 0 | L10: =K10/17 -> 0 | M10: =K10*H10 -> 0 | N10: 0 | O10: =IF(H10="",0,M10-N10) -> 0 | Q10: =O10*P10 -> 0 | R10: =IF(J10=0,O10-Q10,0) -> 0 | S10: =IF(J10=0,0,(J10*K10)-N10-(J10*K10-N10)*P10) -> 0 | T10: =R10+S10 -> 0
J11: =G11-H11-I11 -> 0 | L11: =K11/17 -> 0 | M11: =K11*H11 -> 0 | N11: 0 | O11: =IF(H11="",0,M11-N11) -> 0 | Q11: =O11*P11 -> 0 | R11: =IF(J11=0,O11-Q11,0) -> 0 | S11: =IF(J11=0,0,(J11*K11)-N11-(J11*K11-N11)*P11) -> 0 | T11: =R11+S11 -> 0
J12: =G12-H12-I12 -> 0 | L12: =K12/17 -> 0 | M12: =K12*H12 -> 0 | N12: 0 | O12: =IF(H12="",0,M12-N12) -> 0 | Q12: =O12*P12 -> 0 | R12: =IF(J12=0,O12-Q12,0) -> 0 | S12: =IF(J12=0,0,(J12*K12)-N12-(J12*K12-N12)*P12) -> 0 | T12: =R12+S12 -> 0
J13: =G13-H13-I13 -> 0 | L13: =K13/17 -> 0 | M13: =K13*H13 -> 0 | N13: 0 | O13: =IF(H13="",0,M13-N13) -> 0 | Q13: =O13*P13 -> 0 | R13: =IF(J13=0,O13-Q13,0) -> 0 | S13: =IF(J13=0,0,(J13*K13)-N13-(J13*K13-N13)*P13) -> 0 | T13: =R13+S13 -> 0
J14: =G14-H14-I14 -> 0 | L14: =K14/17 -> 0 | M14: =K14*H14 -> 0 | N14: 0 | O14: =IF(H14="",0,M14-N14) -> 0 | Q14: =O14*P14 -> 0 | R14: =IF(J14=0,O14-Q14,0) -> 0 | S14: =IF(J14=0,0,(J14*K14)-N14-(J14*K14-N14)*P14) -> 0 | T14: =R14+S14 -> 0
J15: =G15-H15-I15 -> 0 | L15: =K15/17 -> 0 | M15: =K15*H15 -> 0 | N15: 0 | O15: =IF(H15="",0,M15-N15) -> 0 | Q15: =O15*P15 -> 0 | R15: =IF(J15=0,O15-Q15,0) -> 0 | S15: =IF(J15=0,0,(J15*K15)-N15-(J15*K15-N15)*P15) -> 0 | T15: =R15+S15 -> 0
J16: =G16-H16-I16 -> 0 | L16: =K16/17 -> 0 | M16: =K16*H16 -> 0 | N16: 0 | O16: =IF(H16="",0,M16-N16) -> 0 | Q16: =O16*P16 -> 0 | R16: =IF(J16=0,O16-Q16,0) -> 0 | S16: =IF(J16=0,0,(J16*K16)-N16-(J16*K16-N16)*P16) -> 0 | T16: =R16+S16 -> 0
J17: =G17-H17-I17 -> 0 | L17: =K17/17 -> 0 | M17: =K17*H17 -> 0 | N17: 0 | O17: =IF(H17="",0,M17-N17) -> 0 | Q17: =O17*P17 -> 0 | R17: =IF(J17=0,O17-Q17,0) -> 0 | S17: =IF(J17=0,0,(J17*K17)-N17-(J17*K17-N17)*P17) -> 0 | T17: =R17+S17 -> 0
... J83: =G83-H83-I83 -> 0 | L83: =K83/17 -> 0 | M83: =K83*H83 -> 0 | N83: 0 | O83: =IF(H83="",0,M83-N83) -> 0 | Q83: =O83*P83 -> 0 | R83: =IF(J83=0,O83-Q83,0) -> 0 | S83: =IF(J83=0,0,(J83*K83)-N83-(J83*K83-N83)*P83) -> 0 | T83: =R83+S83 -> 0
A84: 46057 | J84: =G84-H84-I84 -> 0 | L84: =K84/17 -> 0 | M84: =K84*H84 -> 0 | N84: 0 | O84: =IF(H84="",0,M84-N84) -> 0 | Q84: =O84*P84 -> 0 | R84: =IF(J84=0,O84-Q84,0) -> 0 | S84: =IF(J84=0,0,(J84*K84)-N84-(J84*K84-N84)*P84) -> 0 | T84: =R84+S84 -> 0
J85: =G85-H85-I85 -> 0 | L85: =K85/17 -> 0 | M85: =K85*H85 -> 0 | N85: 0 | O85: =IF(H85="",0,M85-N85) -> 0 | Q85: =O85*P85 -> 0 | R85: =IF(J85=0,O85-Q85,0) -> 0 | S85: =IF(J85=0,0,(J85*K85)-N85-(J85*K85-N85)*P85) -> 0 | T85: =R85+S85 -> 0
J86: =G86-H86-I86 -> 0 | L86: =K86/17 -> 0 | M86: =K86*H86 -> 0 | N86: 0 | O86: =IF(H86="",0,M86-N86) -> 0 | Q86: =O86*P86 -> 0 | R86: =IF(J86=0,O86-Q86,0) -> 0 | S86: =IF(J86=0,0,(J86*K86)-N86-(J86*K86-N86)*P86) -> 0 | T86: =R86+S86 -> 0
J87: =G87-H87-I87 -> 0 | L87: =K87/17 -> 0 | M87: =K87*H87 -> 0 | N87: 0 | O87: =IF(H87="",0,M87-N87) -> 0 | Q87: =O87*P87 -> 0 | R87: =IF(J87=0,O87-Q87,0) -> 0 | S87: =IF(J87=0,0,(J87*K87)-N87-(J87*K87-N87)*P87) -> 0 | T87: =R87+S87 -> 0
J88: =G88-H88-I88 -> 0 | L88: =K88/17 -> 0 | M88: =K88*H88 -> 0 | N88: 0 | O88: =IF(H88="",0,M88-N88) -> 0 | Q88: =O88*P88 -> 0 | R88: =IF(J88=0,O88-Q88,0) -> 0 | S88: =IF(J88=0,0,(J88*K88)-N88-(J88*K88-N88)*P88) -> 0 | T88: =R88+S88 -> 0
J89: =G89-H89-I89 -> 0 | L89: =K89/17 -> 0 | M89: =K89*H89 -> 0 | N89: 0 | O89: =IF(H89="",0,M89-N89) -> 0 | Q89: =O89*P89 -> 0 | R89: =IF(J89=0,O89-Q89,0) -> 0 | S89: =IF(J89=0,0,(J89*K89)-N89-(J89*K89-N89)*P89) -> 0 | T89: =R89+S89 -> 0
J90: =G90-H90-I90 -> 0 | L90: =K90/17 -> 0 | M90: =K90*H90 -> 0 | N90: 0 | O90: =IF(H90="",0,M90-N90) -> 0 | Q90: =O90*P90 -> 0 | R90: =IF(J90=0,O90-Q90,0) -> 0 | S90: =IF(J90=0,0,(J90*K90)-N90-(J90*K90-N90)*P90) -> 0 | T90: =R90+S90 -> 0
J91: =G91-H91-I91 -> 0 | L91: =K91/17 -> 0 | M91: =K91*H91 -> 0 | N91: 0 | O91: =IF(H91="",0,M91-N91) -> 0 | Q91: =O91*P91 -> 0 | R91: =IF(J91=0,O91-Q91,0) -> 0 | S91: =IF(J91=0,0,(J91*K91)-N91-(J91*K91-N91)*P91) -> 0 | T91: =R91+S91 -> 0
J92: =G92-H92-I92 -> 0 | L92: =K92/17 -> 0 | M92: =K92*H92 -> 0 | N92: 0 | O92: =IF(H92="",0,M92-N92) -> 0 | Q92: =O92*P92 -> 0 | R92: =IF(J92=0,O92-Q92,0) -> 0 | S92: =IF(J92=0,0,(J92*K92)-N92-(J92*K92-N92)*P92) -> 0 | T92: =R92+S92 -> 0
J93: =G93-H93-I93 -> 0 | L93: =K93/17 -> 0 | M93: =K93*H93 -> 0 | N93: 0 | O93: =IF(H93="",0,M93-N93) -> 0 | Q93: =O93*P93 -> 0 | R93: =IF(J93=0,O93-Q93,0) -> 0 | S93: =IF(J93=0,0,(J93*K93)-N93-(J93*K93-N93)*P93) -> 0 | T93: =R93+S93 -> 0
J94: =G94-H94-I94 -> 0 | L94: =K94/17 -> 0 | M94: =K94*H94 -> 0 | N94: 0 | O94: =IF(H94="",0,M94-N94) -> 0 | Q94: =O94*P94 -> 0 | R94: =IF(J94=0,O94-Q94,0) -> 0 | S94: =IF(J94=0,0,(J94*K94)-N94-(J94*K94-N94)*P94) -> 0 | T94: =R94+S94 -> 0
J95: =G95-H95-I95 -> 0 | L95: =K95/17 -> 0 | M95: =K95*H95 -> 0 | N95: 0 | O95: =IF(H95="",0,M95-N95) -> 0 | Q95: =O95*P95 -> 0 | R95: =IF(J95=0,O95-Q95,0) -> 0 | S95: =IF(J95=0,0,(J95*K95)-N95-(J95*K95-N95)*P95) -> 0 | T95: =R95+S95 -> 0
J96: =G96-H96-I96 -> 0 | L96: =K96/17 -> 0 | M96: =K96*H96 -> 0 | N96: 0 | O96: =IF(H96="",0,M96-N96) -> 0 | Q96: =O96*P96 -> 0 | R96: =IF(J96=0,O96-Q96,0) -> 0 | S96: =IF(J96=0,0,(J96*K96)-N96-(J96*K96-N96)*P96) -> 0 | T96: =R96+S96 -> 0
... J104: =G104-H104-I104 -> 0 | L104: =K104/17 -> 0 | M104: =K104*H104 -> 0 | N104: 0 | O104: =IF(H104="",0,M104-N104) -> 0 | Q104: =O104*P104 -> 0 | R104: =IF(J104=0,O104-Q104,0) -> 0 | S104: =IF(J104=0,0,(J104*K104)-N104-(J104*K104-N104)*P104) -> 0 | T104: =R104+S104 -> 0

Sheet Roma
F2: TOTAL | G2: =SUM(G4:G495) -> 1757 | H2: =SUM(H4:H495) -> 1757 | I2: =SUM(I4:I495) -> 0 | J2: =SUM(J4:J495) -> 0 | K2: =R2/H2 -> 443.0454 | L2: =O2/(G2*17) -> 28.957216 | M2: =SUM(M4:M495) -> 864923.07 | N2: =SUM(N4:N495) -> 0 | O2: =SUM(O4:O495) -> 864923.07 | P2: =Q2/O2 -> 0.1 | Q2: =SUM(Q4:Q495) -> 86492.307 | R2: =SUM(R4:R495) -> 778430.76 | S2: =SUM(S4:S495) -> 0 | T2: =SUM(T4:T495) -> 778430.76
B3: Fecha | C3: Manifiesto | D3: Agricultor | E3: Cliente | F3: Producto | G3: Enviadas | H3: Reportadas | I3: Merma | J3: x reportar | K3: Precio | L3: $ KG | M3: Venta | N3: Gastos | O3: Subtotal | P3: Comisión | Q3: Comisión CBE | R3: Total | S3: Estimado | T3: Real + Est
B4: 46135 | C4: 19 | D4: H2E | E4: Efrén Medina | F4: Tomate | G4: 34 | H4: 34 | J4: =G4-H4-I4 -> 0 | K4: 600 | L4: =O4/H4/12.5 -> 48 | M4: =K4*H4 -> 20400 | N4: 0 | O4: =IF(H4="",0,M4-N4) -> 20400 | P4: 0.1 | Q4: =O4*P4 -> 2040 | R4: =IF(J4=0,O4-Q4,0) -> 18360 | S4: =IF(J4=0,0,(J4*K4)-N4-(J4*K4-N4)*P4) -> 0 | T4: =R4+S4 -> 18360
B5: 46140 | C5: 25 | D5: H2E | E5: Carlos Perez | F5: Tomate | G5: 83 | H5: 83 | J5: =G5-H5-I5 -> 0 | K5: 653.31 | L5: =O5/H5/12.5 -> 52.2648 | M5: =K5*H5 -> 54224.73 | N5: 0 | O5: =IF(H5="",0,M5-N5) -> 54224.73 | P5: 0.1 | Q5: =O5*P5 -> 5422.473 | R5: =IF(J5=0,O5-Q5,0) -> 48802.257 | S5: =IF(J5=0,0,(J5*K5)-N5-(J5*K5-N5)*P5) -> 0 | T5: =R5+S5 -> 48802.257
B6: 46142 | C6: 26 | D6: H2E | E6: Efrén Medina | F6: Tomate | G6: 101 | H6: 101 | J6: =G6-H6-I6 -> 0 | K6: 648.12 | L6: =K6/17 -> 38.124706 | M6: =K6*H6 -> 65460.12 | N6: 0 | O6: =IF(H6="",0,M6-N6) -> 65460.12 | P6: 0.1 | Q6: =O6*P6 -> 6546.012 | R6: =IF(J6=0,O6-Q6,0) -> 58914.108 | S6: =IF(J6=0,0,(J6*K6)-N6-(J6*K6-N6)*P6) -> 0 | T6: =R6+S6 -> 58914.108
B7: 46144 | C7: 31 | D7: H2E | E7: Carlos Perez | F7: Tomate | G7: 171 | H7: 171 | J7: =G7-H7-I7 -> 0 | K7: 648.83 | L7: =K7/17 -> 38.166471 | M7: =K7*H7 -> 110949.93 | N7: 0 | O7: =IF(H7="",0,M7-N7) -> 110949.93 | P7: 0.1 | Q7: =O7*P7 -> 11094.993 | R7: =IF(J7=0,O7-Q7,0) -> 99854.937 | S7: =IF(J7=0,0,(J7*K7)-N7-(J7*K7-N7)*P7) -> 0 | T7: =R7+S7 -> 99854.937
B8: 46147 | C8: 33 | D8: H2E | E8: Luis Carlos Cejudo | F8: Tomate | G8: 211 | H8: 211 | J8: =G8-H8-I8 -> 0 | K8: =639.05 -> 639.05 | L8: =K8/17 -> 37.591176 | M8: =K8*H8 -> 134839.55 | N8: 0 | O8: =IF(H8="",0,M8-N8) -> 134839.55 | P8: 0.1 | Q8: =O8*P8 -> 13483.955 | R8: =IF(J8=0,O8-Q8,0) -> 121355.59 | S8: =IF(J8=0,0,(J8*K8)-N8-(J8*K8-N8)*P8) -> 0 | T8: =R8+S8 -> 121355.59
B9: 46149 | C9: 35 | D9: H2E | E9: Mayojoa | F9: Tomate | G9: 1 | H9: 1 | J9: =G9-H9-I9 -> 0 | K9: 620 | L9: =K9/17 -> 36.470588 | M9: =K9*H9 -> 620 | N9: 0 | O9: =IF(H9="",0,M9-N9) -> 620 | P9: 0.1 | Q9: =O9*P9 -> 62 | R9: =IF(J9=0,O9-Q9,0) -> 558 | S9: =IF(J9=0,0,(J9*K9)-N9-(J9*K9-N9)*P9) -> 0 | T9: =R9+S9 -> 558
B10: 46150 | C10: 38 | D10: H2E | E10: Mayojoa | F10: Tomate | G10: 50 | H10: 50 | J10: =G10-H10-I10 -> 0 | K10: 480 | L10: =K10/17 -> 28.235294 | M10: =K10*H10 -> 24000 | N10: 0 | O10: =IF(H10="",0,M10-N10) -> 24000 | P10: 0.1 | Q10: =O10*P10 -> 2400 | R10: =IF(J10=0,O10-Q10,0) -> 21600 | S10: =IF(J10=0,0,(J10*K10)-N10-(J10*K10-N10)*P10) -> 0 | T10: =R10+S10 -> 21600
B11: 46150 | C11: 39 | D11: H2E | E11: Carlos Perez | F11: Tomate | G11: 240 | H11: 240 | J11: =G11-H11-I11 -> 0 | K11: 450 | L11: =K11/17 -> 26.470588 | M11: =K11*H11 -> 108000 | N11: 0 | O11: =IF(H11="",0,M11-N11) -> 108000 | P11: 0.1 | Q11: =O11*P11 -> 10800 | R11: =IF(J11=0,O11-Q11,0) -> 97200 | S11: =IF(J11=0,0,(J11*K11)-N11-(J11*K11-N11)*P11) -> 0 | T11: =R11+S11 -> 97200
B12: 46151 | C12: 41 | D12: H2E | E12: Samuel Cuadras | F12: Tomate | G12: 7 | H12: 7 | J12: =G12-H12-I12 -> 0 | K12: 460 | L12: =K12/17 -> 27.058824 | M12: =K12*H12 -> 3220 | N12: 0 | O12: =IF(H12="",0,M12-N12) -> 3220 | P12: 0.1 | Q12: =O12*P12 -> 322 | R12: =IF(J12=0,O12-Q12,0) -> 2898 | S12: =IF(J12=0,0,(J12*K12)-N12-(J12*K12-N12)*P12) -> 0 | T12: =R12+S12 -> 2898
B13: 46153 | C13: 42 | D13: H2E | E13: Epifanio Lopez | F13: Tomate | G13: 80 | H13: 80 | J13: =G13-H13-I13 -> 0 | K13: 430 | L13: =K13/17 -> 25.294118 | M13: =K13*H13 -> 34400 | N13: 0 | O13: =IF(H13="",0,M13-N13) -> 34400 | P13: 0.1 | Q13: =O13*P13 -> 3440 | R13: =IF(J13=0,O13-Q13,0) -> 30960 | S13: =IF(J13=0,0,(J13*K13)-N13-(J13*K13-N13)*P13) -> 0 | T13: =R13+S13 -> 30960
B14: 46153 | C14: 43 | D14: H2E | E14: Mayojoa | F14: Tomate | G14: 39 | H14: 39 | J14: =G14-H14-I14 -> 0 | K14: 388.46 | L14: =K14/17 -> 22.850588 | M14: =K14*H14 -> 15149.94 | N14: 0 | O14: =IF(H14="",0,M14-N14) -> 15149.94 | P14: 0.1 | Q14: =O14*P14 -> 1514.994 | R14: =IF(J14=0,O14-Q14,0) -> 13634.946 | S14: =IF(J14=0,0,(J14*K14)-N14-(J14*K14-N14)*P14) -> 0 | T14: =R14+S14 -> 13634.946
B15: 46153 | C15: 44 | D15: H2E | E15: Efrén Medina | F15: Tomate | G15: 240 | H15: 240 | J15: =G15-H15-I15 -> 0 | K15: 400 | L15: =K15/17 -> 23.529412 | M15: =K15*H15 -> 96000 | N15: 0 | O15: =IF(H15="",0,M15-N15) -> 96000 | P15: 0.1 | Q15: =O15*P15 -> 9600 | R15: =IF(J15=0,O15-Q15,0) -> 86400 | S15: =IF(J15=0,0,(J15*K15)-N15-(J15*K15-N15)*P15) -> 0 | T15: =R15+S15 -> 86400
B16: 46153 | C16: 45 | D16: H2E | E16: Bodega Lizarraga | F16: Tomate | G16: 330 | H16: 330 | J16: =G16-H16-I16 -> 0 | K16: 398.36 | L16: =K16/17 -> 23.432941 | M16: =K16*H16 -> 131458.8 | N16: 0 | O16: =IF(H16="",0,M16-N16) -> 131458.8 | P16: 0.1 | Q16: =O16*P16 -> 13145.88 | R16: =IF(J16=0,O16-Q16,0) -> 118312.92 | S16: =IF(J16=0,0,(J16*K16)-N16-(J16*K16-N16)*P16) -> 0 | T16: =R16+S16 -> 118312.92
B17: 46155 | C17: 47 | D17: H2E | E17: Mayojoa | F17: Tomate | G17: 70 | H17: 70 | J17: =G17-H17-I17 -> 0 | K17: 380 | L17: =K17/17 -> 22.352941 | M17: =K17*H17 -> 26600 | N17: 0 | O17: =IF(H17="",0,M17-N17) -> 26600 | P17: 0.1 | Q17: =O17*P17 -> 2660 | R17: =IF(J17=0,O17-Q17,0) -> 23940 | S17: =IF(J17=0,0,(J17*K17)-N17-(J17*K17-N17)*P17) -> 0 | T17: =R17+S17 -> 23940
B18: 46155 | C18: 48 | D18: H2E | E18: Epifanio Lopez | F18: Tomate | G18: 80 | H18: 80 | J18: =G18-H18-I18 -> 0 | K18: 400 | L18: =K18/17 -> 23.529412 | M18: =K18*H18 -> 32000 | N18: 0 | O18: =IF(H18="",0,M18-N18) -> 32000 | P18: 0.1 | Q18: =O18*P18 -> 3200 | R18: =IF(J18=0,O18-Q18,0) -> 28800 | S18: =IF(J18=0,0,(J18*K18)-N18-(J18*K18-N18)*P18) -> 0 | T18: =R18+S18 -> 28800
B19: 46155 | C19: 49 | D19: H2E | E19: Mayojoa | F19: Tomate | G19: 20 | H19: 20 | J19: =G19-H19-I19 -> 0 | K19: 380 | L19: =K19/17 -> 22.352941 | M19: =K19*H19 -> 7600 | N19: 0 | O19: =IF(H19="",0,M19-N19) -> 7600 | P19: 0.1 | Q19: =O19*P19 -> 760 | R19: =IF(J19=0,O19-Q19,0) -> 6840 | S19: =IF(J19=0,0,(J19*K19)-N19-(J19*K19-N19)*P19) -> 0 | T19: =R19+S19 -> 6840
J20: =G20-H20-I20 -> 0 | L20: =K20/17 -> 0 | M20: =K20*H20 -> 0 | N20: 0 | O20: =IF(H20="",0,M20-N20) -> 0 | Q20: =O20*P20 -> 0 | R20: =IF(J20=0,O20-Q20,0) -> 0 | S20: =IF(J20=0,0,(J20*K20)-N20-(J20*K20-N20)*P20) -> 0 | T20: =R20+S20 -> 0
J21: =G21-H21-I21 -> 0 | L21: =K21/17 -> 0 | M21: =K21*H21 -> 0 | N21: 0 | O21: =IF(H21="",0,M21-N21) -> 0 | Q21: =O21*P21 -> 0 | R21: =IF(J21=0,O21-Q21,0) -> 0 | S21: =IF(J21=0,0,(J21*K21)-N21-(J21*K21-N21)*P21) -> 0 | T21: =R21+S21 -> 0
J22: =G22-H22-I22 -> 0 | L22: =K22/17 -> 0 | M22: =K22*H22 -> 0 | N22: 0 | O22: =IF(H22="",0,M22-N22) -> 0 | Q22: =O22*P22 -> 0 | R22: =IF(J22=0,O22-Q22,0) -> 0 | S22: =IF(J22=0,0,(J22*K22)-N22-(J22*K22-N22)*P22) -> 0 | T22: =R22+S22 -> 0
J23: =G23-H23-I23 -> 0 | L23: =K23/17 -> 0 | M23: =K23*H23 -> 0 | N23: 0 | O23: =IF(H23="",0,M23-N23) -> 0 | Q23: =O23*P23 -> 0 | R23: =IF(J23=0,O23-Q23,0) -> 0 | S23: =IF(J23=0,0,(J23*K23)-N23-(J23*K23-N23)*P23) -> 0 | T23: =R23+S23 -> 0
J24: =G24-H24-I24 -> 0 | L24: =K24/17 -> 0 | M24: =K24*H24 -> 0 | N24: 0 | O24: =IF(H24="",0,M24-N24) -> 0 | Q24: =O24*P24 -> 0 | R24: =IF(J24=0,O24-Q24,0) -> 0 | S24: =IF(J24=0,0,(J24*K24)-N24-(J24*K24-N24)*P24) -> 0 | T24: =R24+S24 -> 0
J25: =G25-H25-I25 -> 0 | L25: =K25/17 -> 0 | M25: =K25*H25 -> 0 | N25: 0 | O25: =IF(H25="",0,M25-N25) -> 0 | Q25: =O25*P25 -> 0 | R25: =IF(J25=0,O25-Q25,0) -> 0 | S25: =IF(J25=0,0,(J25*K25)-N25-(J25*K25-N25)*P25) -> 0 | T25: =R25+S25 -> 0
J26: =G26-H26-I26 -> 0 | L26: =K26/17 -> 0 | M26: =K26*H26 -> 0 | N26: 0 | O26: =IF(H26="",0,M26-N26) -> 0 | Q26: =O26*P26 -> 0 | R26: =IF(J26=0,O26-Q26,0) -> 0 | S26: =IF(J26=0,0,(J26*K26)-N26-(J26*K26-N26)*P26) -> 0 | T26: =R26+S26 -> 0
J27: =G27-H27-I27 -> 0 | L27: =K27/17 -> 0 | M27: =K27*H27 -> 0 | N27: 0 | O27: =IF(H27="",0,M27-N27) -> 0 | Q27: =O27*P27 -> 0 | R27: =IF(J27=0,O27-Q27,0) -> 0 | S27: =IF(J27=0,0,(J27*K27)-N27-(J27*K27-N27)*P27) -> 0 | T27: =R27+S27 -> 0
J28: =G28-H28-I28 -> 0 | L28: =K28/17 -> 0 | M28: =K28*H28 -> 0 | N28: 0 | O28: =IF(H28="",0,M28-N28) -> 0 | Q28: =O28*P28 -> 0 | R28: =IF(J28=0,O28-Q28,0) -> 0 | S28: =IF(J28=0,0,(J28*K28)-N28-(J28*K28-N28)*P28) -> 0 | T28: =R28+S28 -> 0
J29: =G29-H29-I29 -> 0 | L29: =K29/17 -> 0 | M29: =K29*H29 -> 0 | N29: 0 | O29: =IF(H29="",0,M29-N29) -> 0 | Q29: =O29*P29 -> 0 | R29: =IF(J29=0,O29-Q29,0) -> 0 | S29: =IF(J29=0,0,(J29*K29)-N29-(J29*K29-N29)*P29) -> 0 | T29: =R29+S29 -> 0
J30: =G30-H30-I30 -> 0 | L30: =K30/17 -> 0 | M30: =K30*H30 -> 0 | N30: 0 | O30: =IF(H30="",0,M30-N30) -> 0 | Q30: =O30*P30 -> 0 | R30: =IF(J30=0,O30-Q30,0) -> 0 | S30: =IF(J30=0,0,(J30*K30)-N30-(J30*K30-N30)*P30) -> 0 | T30: =R30+S30 -> 0
J31: =G31-H31-I31 -> 0 | L31: =K31/17 -> 0 | M31: =K31*H31 -> 0 | N31: 0 | O31: =IF(H31="",0,M31-N31) -> 0 | Q31: =O31*P31 -> 0 | R31: =IF(J31=0,O31-Q31,0) -> 0 | S31: =IF(J31=0,0,(J31*K31)-N31-(J31*K31-N31)*P31) -> 0 | T31: =R31+S31 -> 0
... J84: =G84-H84-I84 -> 0 | L84: =K84/17 -> 0 | M84: =K84*H84 -> 0 | N84: 0 | O84: =IF(H84="",0,M84-N84) -> 0 | Q84: =O84*P84 -> 0 | R84: =IF(J84=0,O84-Q84,0) -> 0 | S84: =IF(J84=0,0,(J84*K84)-N84-(J84*K84-N84)*P84) -> 0 | T84: =R84+S84 -> 0
A85: 46057 | J85: =G85-H85-I85 -> 0 | L85: =K85/17 -> 0 | M85: =K85*H85 -> 0 | N85: 0 | O85: =IF(H85="",0,M85-N85) -> 0 | Q85: =O85*P85 -> 0 | R85: =IF(J85=0,O85-Q85,0) -> 0 | S85: =IF(J85=0,0,(J85*K85)-N85-(J85*K85-N85)*P85) -> 0 | T85: =R85+S85 -> 0
J86: =G86-H86-I86 -> 0 | L86: =K86/17 -> 0 | M86: =K86*H86 -> 0 | N86: 0 | O86: =IF(H86="",0,M86-N86) -> 0 | Q86: =O86*P86 -> 0 | R86: =IF(J86=0,O86-Q86,0) -> 0 | S86: =IF(J86=0,0,(J86*K86)-N86-(J86*K86-N86)*P86) -> 0 | T86: =R86+S86 -> 0
J87: =G87-H87-I87 -> 0 | L87: =K87/17 -> 0 | M87: =K87*H87 -> 0 | N87: 0 | O87: =IF(H87="",0,M87-N87) -> 0 | Q87: =O87*P87 -> 0 | R87: =IF(J87=0,O87-Q87,0) -> 0 | S87: =IF(J87=0,0,(J87*K87)-N87-(J87*K87-N87)*P87) -> 0 | T87: =R87+S87 -> 0
J88: =G88-H88-I88 -> 0 | L88: =K88/17 -> 0 | M88: =K88*H88 -> 0 | N88: 0 | O88: =IF(H88="",0,M88-N88) -> 0 | Q88: =O88*P88 -> 0 | R88: =IF(J88=0,O88-Q88,0) -> 0 | S88: =IF(J88=0,0,(J88*K88)-N88-(J88*K88-N88)*P88) -> 0 | T88: =R88+S88 -> 0
J89: =G89-H89-I89 -> 0 | L89: =K89/17 -> 0 | M89: =K89*H89 -> 0 | N89: 0 | O89: =IF(H89="",0,M89-N89) -> 0 | Q89: =O89*P89 -> 0 | R89: =IF(J89=0,O89-Q89,0) -> 0 | S89: =IF(J89=0,0,(J89*K89)-N89-(J89*K89-N89)*P89) -> 0 | T89: =R89+S89 -> 0
J90: =G90-H90-I90 -> 0 | L90: =K90/17 -> 0 | M90: =K90*H90 -> 0 | N90: 0 | O90: =IF(H90="",0,M90-N90) -> 0 | Q90: =O90*P90 -> 0 | R90: =IF(J90=0,O90-Q90,0) -> 0 | S90: =IF(J90=0,0,(J90*K90)-N90-(J90*K90-N90)*P90) -> 0 | T90: =R90+S90 -> 0
J91: =G91-H91-I91 -> 0 | L91: =K91/17 -> 0 | M91: =K91*H91 -> 0 | N91: 0 | O91: =IF(H91="",0,M91-N91) -> 0 | Q91: =O91*P91 -> 0 | R91: =IF(J91=0,O91-Q91,0) -> 0 | S91: =IF(J91=0,0,(J91*K91)-N91-(J91*K91-N91)*P91) -> 0 | T91: =R91+S91 -> 0
J92: =G92-H92-I92 -> 0 | L92: =K92/17 -> 0 | M92: =K92*H92 -> 0 | N92: 0 | O92: =IF(H92="",0,M92-N92) -> 0 | Q92: =O92*P92 -> 0 | R92: =IF(J92=0,O92-Q92,0) -> 0 | S92: =IF(J92=0,0,(J92*K92)-N92-(J92*K92-N92)*P92) -> 0 | T92: =R92+S92 -> 0
J93: =G93-H93-I93 -> 0 | L93: =K93/17 -> 0 | M93: =K93*H93 -> 0 | N93: 0 | O93: =IF(H93="",0,M93-N93) -> 0 | Q93: =O93*P93 -> 0 | R93: =IF(J93=0,O93-Q93,0) -> 0 | S93: =IF(J93=0,0,(J93*K93)-N93-(J93*K93-N93)*P93) -> 0 | T93: =R93+S93 -> 0
...

Sheet Estado de Cuenta T
B1: VENTAS | I1: =I2/(F2*17) -> 10.55029 | J1: x kg
C2: Total | F2: =SUM(F4:F391) -> 5893 | G2: =I2/F2 -> 179.35492 | H2: =SUM(H4:H391) -> 4400 | I2: =SUM(I4:I391) -> 1056938.6 | J2: =O39 -> 731832 | K2: =O45 -> 325106.56 | L2: Est Pen x Pagar | O2: PAGOS
B3: Fecha | C3: Manifiesto | D3: Liquidación | E3: Cliente | F3: Cajas | G3: Precio | H3: Gastos | I3: Monto | J3: Pago a H2E | K3: 0 | L3: Cajas x Reportar | N3: Fecha | O3: Monto
B4: =Tomatillo!B4 -> 46128 | C4: =Tomatillo!C4 -> 1 | D4: 20260416-01 | E4: =Tomatillo!E4 -> Carlos Perez | F4: =Tomatillo!G4 -> 50 | G4: =Tomatillo!K4 -> 306 | H4: =Tomatillo!N4 -> 0 | I4: =F4*G4-H4 -> 15300 | J4: Pagado | K4: =[1]VENTAS!R2 -> 691969.5 | L4: Ret Est H2E | N4: 46128 | O4: 36720
B5: =Tomatillo!B5 -> 46128 | C5: =Tomatillo!C5 -> 2 | D5: 20260416-02 | E5: =Tomatillo!E5 -> Carlos Perez | F5: =Tomatillo!G5 -> 10 | G5: =Tomatillo!K5 -> 306 | H5: =Tomatillo!N5 -> 0 | I5: =F5*G5-H5 -> 3060 | J5: Pagado | N5: 46129 | O5: 78948
B6: =Tomatillo!B6 -> 46128 | C6: =Tomatillo!C6 -> 3 | D6: 20260416-03 | E6: =Tomatillo!E6 -> Mayojoa | F6: =Tomatillo!G6 -> 20 | G6: =Tomatillo!K6 -> 306 | H6: =Tomatillo!N6 -> 0 | I6: =F6*G6-H6 -> 6120 | J6: Pagado | N6: 46133 | O6: 40086
B7: =Tomatillo!B7 -> 46128 | C7: =Tomatillo!C7 -> 4 | D7: 20260416-04 | E7: =Tomatillo!E7 -> Luis Carlos Cejudo | F7: =Tomatillo!G7 -> 48 | G7: =Tomatillo!K7 -> 255 | H7: =Tomatillo!N7 -> 0 | I7: =F7*G7-H7 -> 12240 | J7: Pagado | K7: =95764/(434*17) -> 12.979669 | N7: 46135 | O7: 123114
B8: =Tomatillo!B8 -> 46128 | C8: =Tomatillo!C8 -> 5 | D8: 20260416-05 | E8: =Tomatillo!E8 -> Bodega Lizarraga | F8: =Tomatillo!G8 -> 384 | G8: =Tomatillo!K8 -> 289 | H8: =Tomatillo!N8 -> 0 | I8: =F8*G8-H8 -> 110976 | J8: Pagado | N8: 46136 | O8: 100000
B9: =Tomatillo!B9 -> 46129 | C9: =Tomatillo!C9 -> 7 | D9: 20260417-01 | E9: =Tomatillo!E9 -> Mayojoa | F9: =Tomatillo!G9 -> 50 | G9: =Tomatillo!K9 -> 306 | H9: 0 | I9: =F9*G9-H9 -> 15300 | J9: Pagado | K9: =G9/17 -> 18 | N9: 46136 | O9: 100000
B10: =Tomatillo!B10 -> 46129 | C10: =Tomatillo!C10 -> 9 | D10: 20260417-02 | E10: =Tomatillo!E10 -> Porfirio Casarez | F10: =Tomatillo!G10 -> 288 | G10: =Tomatillo!K10 -> 221 | H10: 0 | I10: =F10*G10-H10 -> 63648 | J10: Pagado | K10: =G10/17 -> 13 | N10: 46136 | O10: 5530
B11: =Tomatillo!B11 -> 46129 | C11: =Tomatillo!C11 -> 10 | D11: 20260417-03 | E11: =Tomatillo!E11 -> Jorge Luis Zazueta | F11: =Tomatillo!G11 -> 96 | G11: =Tomatillo!K11 -> 221 | H11: =Tomatillo!N11 -> 4400 | I11: =F11*G11-H11 -> 16816 | J11: Pendiente | K11: =G11/17 -> 13 | L11: =H11/(F11*17) -> 2.6960784 | N11: 46140 | O11: 6120
B12: =Tomatillo!B12 -> 46130 | C12: =Tomatillo!C12 -> 11 | D12: 20260418-01 | E12: =Tomatillo!E12 -> Carlos Perez | F12: =Tomatillo!G12 -> 147 | G12: =Tomatillo!K12 -> 238 | H12: =Tomatillo!N12 -> 0 | I12: =F12*G12-H12 -> 34986 | J12: Pagado | K12: =G12/17 -> 14 | N12: 46142 | O12: 110976
B13: =Tomatillo!B13 -> 46130 | C13: =Tomatillo!C13 -> 12 | D13: 20260418-02 | E13: =Tomatillo!E13 -> Ziracua | F13: =Tomatillo!G13 -> 150 | G13: =Tomatillo!K13 -> 289 | H13: =Tomatillo!N13 -> 0 | I13: =F13*G13-H13 -> 43350 | J13: Pagado | K13: =G13/17 -> 17 | N13: 46150 | O13: 7021
B14: =Tomatillo!B14 -> 46132 | C14: =Tomatillo!C14 -> 13 | D14: 20260420-01 | E14: =Tomatillo!E14 -> Mayojoa | F14: =Tomatillo!G14 -> 20 | G14: =Tomatillo!K14 -> 255 | H14: =Tomatillo!N14 -> 0 | I14: =F14*G14-H14 -> 5100 | J14: Pagado | K14: =G14/17 -> 15 | N14: 46151 | O14: 97750
B15: =Tomatillo!B15 -> 46132 | C15: =Tomatillo!C15 -> 14 | D15: 20260420-02 | E15: =Tomatillo!E15 -> Efrén Medina | F15: =Tomatillo!G15 -> 150 | G15: =Tomatillo!K15 -> 255 | H15: =Tomatillo!N15 -> 0 | I15: =F15*G15-H15 -> 38250 | J15: Pagado | K15: =G15/17 -> 15 | N15: 46154 | O15: =16320+9247 -> 25567
B16: =Tomatillo!B16 -> 46133 | C16: =Tomatillo!C16 -> 16 | D16: 20260421-02 | E16: =Tomatillo!E16 -> Ziracua | F16: =Tomatillo!G16 -> 200 | G16: =Tomatillo!K16 -> 272 | H16: =Tomatillo!N16 -> 0 | I16: =F16*G16-H16 -> 54400 | J16: Pagado
B17: =Tomatillo!B17 -> 46133 | C17: =Tomatillo!C17 -> 16 | D17: 20260421-02 | E17: =Tomatillo!E17 -> Ziracua | F17: =Tomatillo!G17 -> 3 | G17: =Tomatillo!K17 -> 0 | H17: =Tomatillo!N17 -> 0 | I17: =F17*G17-H17 -> 0
B18: =Tomatillo!B18 -> 46134 | C18: =Tomatillo!C18 -> 17 | D18: 20260422-01 | E18: =Tomatillo!E18 -> Frutierrez | F18: =Tomatillo!G18 -> 48 | G18: =Tomatillo!K18 -> 255 | H18: =Tomatillo!N18 -> 0 | I18: =F18*G18-H18 -> 12240 | J18: Pendiente
B19: =Tomatillo!B19 -> 46134 | C19: =Tomatillo!C19 -> 18 | D19: 20260422-02 | E19: =Tomatillo!E19 -> Porfirio Casarez | F19: =Tomatillo!G19 -> 624 | G19: =Tomatillo!K19 -> 136 | H19: =Tomatillo!N19 -> 0 | I19: =F19*G19-H19 -> 84864 | J19: Pagado
B20: =Tomatillo!B20 -> 46136 | C20: =Tomatillo!C20 -> 20 | D20: 20260424-01 | E20: =Tomatillo!E20 -> Carlos Perez | F20: =Tomatillo!G20 -> 30 | G20: =Tomatillo!K20 -> 204 | H20: 0 | I20: =F20*G20-H20 -> 6120 | J20: Pagado
B21: =Tomatillo!B21 -> 46046 | C21: =Tomatillo!C21 -> 21 | D21: 202604424-02 | E21: =Tomatillo!E21 -> Porfirio Casarez | F21: =Tomatillo!G21 -> 1209 | G21: =Tomatillo!K21 -> 170 | H21: 0 | I21: =F21*G21-H21 -> 205530 | J21: Pagado
B22: =Tomatillo!B22 -> 46137 | C22: =Tomatillo!C22 -> 23 | D22: 202604425-01 | E22: =Tomatillo!E22 -> Carlos Perez | F22: =Tomatillo!G22 -> 30 | G22: =Tomatillo!K22 -> 204 | H22: 0 | I22: =F22*G22-H22 -> 6120 | J22: Pendiente
B23: =Tomatillo!B23 -> 46142 | C23: =Tomatillo!C23 -> 27 | D23: 202604425-02 | E23: =Tomatillo!E23 -> Samuel Cuadras | F23: =Tomatillo!G23 -> 21 | G23: =Tomatillo!K23 -> 204 | H23: 0 | I23: =F23*G23-H23 -> 4284 | J23: Pendiente
B24: =Tomatillo!B24 -> 46142 | C24: =Tomatillo!C24 -> 28 | D24: 202604425-03 | E24: =Tomatillo!E24 -> Bodega Lizarraga | F24: =Tomatillo!G24 -> 384 | G24: =Tomatillo!K24 -> 204 | H24: 0 | I24: =F24*G24-H24 -> 78336 | J24: Pendiente
B25: =Tomatillo!B25 -> 46143 | C25: =Tomatillo!C25 -> 29 | D25: 202604425-04 | E25: =Tomatillo!E25 -> Efrén Medina | F25: =Tomatillo!G25 -> 80 | G25: =Tomatillo!K25 -> 221 | H25: 0 | I25: =F25*G25-H25 -> 17680 | J25: Pendiente
B26: =Tomatillo!B26 -> 46146 | C26: =Tomatillo!C26 -> 32 | D26: 20260504-01 | E26: =Tomatillo!E26 -> Porfirio Casarez | F26: =Tomatillo!G26 -> 1248 | G26: =Tomatillo!K26 -> 104.04 | H26: 0 | I26: =F26*G26-H26 -> 129841.92 | J26: Pendiente
B27: =Tomatillo!B27 -> 46147 | C27: =Tomatillo!C27 -> 34 | D27: 20260505-02 | E27: =Tomatillo!E27 -> Bodega Lizarraga | F27: =Tomatillo!G27 -> 319 | G27: =Tomatillo!K27 -> 187 | H27: 0 | I27: =F27*G27-H27 -> 59653 | J27: Pendiente
B28: =Tomatillo!B28 -> 46149 | C28: =Tomatillo!C28 -> 35 | D28: 20260507-01 | E28: =Tomatillo!E28 -> Mayojoa | F28: =Tomatillo!G28 -> 1 | G28: =Tomatillo!K28 -> 136 | H28: 0 | I28: =F28*G28-H28 -> 136 | J28: Pagado
B29: =Tomatillo!B29 -> 46149 | C29: =Tomatillo!C29 -> 36 | D29: 20260507-02 | E29: =Tomatillo!E29 -> Mayojoa | F29: =Tomatillo!G29 -> 59 | G29: =Tomatillo!K29 -> 119 | H29: 0 | I29: =F29*G29-H29 -> 7021 | J29: Pagado
B30: =Tomatillo!B30 -> 46150 | C30: =Tomatillo!C30 -> 37 | D30: 20260508-01 | E30: =Tomatillo!E30 -> Efrén Medina | F30: =Tomatillo!G30 -> 120 | G30: =Tomatillo!K30 -> 136 | H30: 0 | I30: =F30*G30-H30 -> 16320 | J30: Pagado
B31: =Tomatillo!B31 -> 46154 | C31: =Tomatillo!C31 -> 46 | D31: 20260512-01 | E31: =Tomatillo!E31 -> Mayojoa | F31: =Tomatillo!G31 -> 104 | G31: =Tomatillo!K31 -> 88.91 | H31: 0 | I31: =F31*G31-H31 -> 9246.64 | J31: Pagado
N39: Total | O39: =SUM(O4:O38) -> 731832
N41: Retorno Com | O41: =Tomatillo!Q2 -> 92709.664
N43: vta est | O43: =Tomatillo!T2 -> 964228.9
N45: balance est | O45: =+O43+O41-O39 -> 325106.56

Sheet Estado de Cuenta R
B1: VENTAS | I1: =I2/(F2*17) -> 28.964809 | J1: x kg
C2: Total | F2: =SUM(F4:F390) -> 1750 | G2: =I2/F2 -> 492.40175 | H2: =SUM(H4:H390) -> 0 | I2: =SUM(I4:I390) -> 861703.07 | J2: =O38 -> 702245 | K2: =O44 -> 162678.07 | L2: Est Pen x Pagar | O2: PAGOS
B3: Fecha | C3: Manifiesto | D3: Liquidación | E3: Cliente | F3: Cajas | G3: Precio | H3: Gastos | I3: Monto | J3: Pago a H2E | K3: 0 | L3: Cajas x Reportar | N3: Fecha | O3: Monto
B4: 46135 | C4: 19 | D4: 20260423-01 | E4: Efrén Medina | F4: 34 | G4: 600 | H4: 0 | I4: =F4*G4-H4 -> 20400 | J4: Pendiente | K4: =[1]VENTAS!R2 -> 691969.5 | L4: Ret Est H2E | N4: 46140 | O4: 54225
B5: =Roma!B5 -> 46140 | C5: =Roma!C5 -> 25 | D5: 20260428-01 | E5: =Roma!E5 -> Carlos Perez | F5: =Roma!H5 -> 83 | G5: =Roma!K5 -> 653.31 | H5: =Roma!N5 -> 0 | I5: =Roma!O5 -> 54224.73 | J5: Pagado | N5: 46142 | O5: 65460
B6: =Roma!B6 -> 46142 | C6: =Roma!C6 -> 26 | D6: 20260430-01 | E6: =Roma!E6 -> Efrén Medina | F6: =Roma!H6 -> 101 | G6: =Roma!K6 -> 648.12 | H6: 0 | I6: =Roma!O6 -> 65460.12 | J6: Pagado | N6: 46146 | O6: 110950
B7: =Roma!B7 -> 46144 | C7: =Roma!C7 -> 31 | D7: 20260502-01 | E7: =Roma!E7 -> Carlos Perez | F7: 171 | G7: 648.83 | H7: 0 | I7: =F7*G7-H7 -> 110949.93 | J7: Pagado | N7: 46148 | O7: 134840
B8: =Roma!B8 -> 46147 | C8: =Roma!C8 -> 33 | D8: 20260505-01 | E8: =Roma!E8 -> Luis Carlos Cejudo | F8: =Roma!H8 -> 211 | G8: =Roma!K8 -> 639.05 | H8: 0 | I8: =F8*G8-H8 -> 134839.55 | J8: Pagado | N8: 46150 | O8: =108000+24000+620 -> 132620
B9: =Roma!B9 -> 46149 | C9: =Roma!C9 -> 35 | D9: 20260507-01 | E9: =Roma!E9 -> Mayojoa | F9: =Roma!H9 -> 1 | G9: =Roma!K9 -> 620 | H9: 0 | I9: =F9*G9-H9 -> 620 | J9: Pagado | N9: 46154 | O9: 145550
B10: =Roma!B10 -> 46150 | C10: =Roma!C10 -> 38 | D10: 20260508-02 | E10: =Roma!E10 -> Mayojoa | F10: =Roma!H10 -> 50 | G10: =Roma!K10 -> 480 | H10: 0 | I10: =F10*G10-H10 -> 24000 | J10: Pagado | N10: 46155 | O10: 58600
B11: =Roma!B11 -> 46150 | C11: =Roma!C11 -> 39 | D11: 20260508-03 | E11: =Roma!E11 -> Carlos Perez | F11: =Roma!H11 -> 240 | G11: =Roma!K11 -> 450 | H11: 0 | I11: =F11*G11-H11 -> 108000 | J11: Pagado
B12: =Roma!B13 -> 46153 | C12: =Roma!C13 -> 42 | D12: 20260511-01 | E12: =Roma!E13 -> Epifanio Lopez | F12: =Roma!H13 -> 80 | G12: =Roma!K13 -> 430 | H12: 0 | I12: =F12*G12-H12 -> 34400 | J12: Pagado
B13: =Roma!B14 -> 46153 | C13: =Roma!C14 -> 43 | D13: 20260511-02 | E13: =Roma!E14 -> Mayojoa | F13: =Roma!H14 -> 39 | G13: =Roma!K14 -> 388.46 | H13: 0 | I13: =F13*G13-H13 -> 15149.94 | J13: Pagado
B14: =Roma!B15 -> 46153 | C14: =Roma!C15 -> 44 | D14: 20260511-03 | E14: =Roma!E15 -> Efrén Medina | F14: =Roma!H15 -> 240 | G14: =Roma!K15 -> 400 | H14: 0 | I14: =F14*G14-H14 -> 96000 | J14: Pagado
B15: =Roma!B16 -> 46153 | C15: =Roma!C16 -> 45 | D15: 20260511-04 | E15: =Roma!E16 -> Bodega Lizarraga | F15: =Roma!H16 -> 330 | G15: =Roma!K16 -> 398.36 | H15: 0 | I15: =F15*G15-H15 -> 131458.8 | J15: Pendiente
B16: =Roma!B17 -> 46155 | C16: =Roma!C17 -> 47 | D16: 20260513-01 | E16: =Roma!E17 -> Mayojoa | F16: =Roma!H17 -> 70 | G16: =Roma!K17 -> 380 | H16: 0 | I16: =F16*G16-H16 -> 26600 | J16: Pagado
B17: =Roma!B18 -> 46155 | C17: =Roma!C18 -> 48 | D17: 20260513-02 | E17: =Roma!E18 -> Epifanio Lopez | F17: =Roma!H18 -> 80 | G17: =Roma!K18 -> 400 | H17: 0 | I17: =F17*G17-H17 -> 32000 | J17: Pagado
B18: =Roma!B19 -> 46155 | C18: =Roma!C19 -> 49 | D18: 20260513-03 | E18: =Roma!E19 -> Mayojoa | F18: =Roma!H19 -> 20 | G18: =Roma!K19 -> 380 | H18: 0 | I18: =F18*G18-H18 -> 7600 | J18: Pendiente
N38: Total | O38: =SUM(O4:O37) -> 702245
N40: Retorno Com | O40: =Roma!Q2 -> 86492.307
N42: vta est | O42: =+Roma!R2 -> 778430.76
N44: balance est | O44: =+O42+O40-O38 -> 162678.07

Sheet Estado de Cuenta M
B1: VENTAS | I1: =I2/(F2*17) -> 14.937611 | J1: x kg
C2: Total | F2: =SUM(F4:F390) -> 33 | G2: =I2/F2 -> 253.93939 | H2: =SUM(H4:H390) -> 0 | I2: =SUM(I4:I390) -> 8380 | J2: =O38 -> 5980 | K2: =O44 -> 2400 | L2: Est Pen x Pagar | O2: PAGOS
B3: Fecha | C3: Manifiesto | D3: Liquidación | E3: Cliente | F3: Cajas | G3: Precio | H3: Gastos | I3: Monto | J3: Pago a H2E | K3: 0 | L3: Cajas x Reportar | N3: Fecha | O3: Monto
B4: =Morrón!B4 -> 46139 | C4: =Morrón!C4 -> 24 | D4: 20260427-01 | E4: =Morrón!E4 -> Samuel Cuadras | F4: =Morrón!G4 -> 10 | G4: =Morrón!K4 -> 240 | H4: 0 | I4: =F4*G4-H4 -> 2400 | J4: Pendiente | K4: =[1]VENTAS!R2 -> 691969.5 | L4: Ret Est H2E | N4: 46154 | O4: 5980
B5: =Morrón!B5 -> 46151 | C5: =Morrón!C5 -> 40 | D5: 20260509-01 | E5: =Morrón!E5 -> Mayojoa | F5: =Morrón!G5 -> 23 | G5: =Morrón!K5 -> 260 | H5: 0 | I5: =F5*G5-H5 -> 5980 | J5: Pagado
H6: 0 | I6: =F6*G6-H6 -> 0
H7: 0 | I7: =F7*G7-H7 -> 0
H8: 0 | I8: =F8*G8-H8 -> 0
H9: 0 | I9: =F9*G9-H9 -> 0
H10: 0 | I10: =F10*G10-H10 -> 0
H11: 0 | I11: =F11*G11-H11 -> 0
H12: 0 | I12: =F12*G12-H12 -> 0
H13: 0 | I13: =F13*G13-H13 -> 0
H14: 0 | I14: =F14*G14-H14 -> 0
H15: 0 | I15: =F15*G15-H15 -> 0
H16: 0 | I16: =F16*G16-H16 -> 0
H17: 0 | I17: =F17*G17-H17 -> 0
H18: 0 | I18: =F18*G18-H18 -> 0
N38: Total | O38: =SUM(O4:O37) -> 5980
N40: Retorno Com | O40: =Morrón!Q2 -> 838
N42: vta est | O42: =+Morrón!R2 -> 7542
N44: balance est | O44: =+O42+O40-O38 -> 2400

Sheet acum
D2: Balance 2da Etapa
E4: venta | F4: pagos | G4: por pagar | I4: comision cbe | J4: comision pagada | K4: balance p/h2e
D5: tomatillo | E5: =+Tomatillo!O2 -> 1056938.6 | F5: =+'Estado de Cuenta T'!O39 -> 731832 | G5: =+E5-F5 -> 325106.56 | I5: =+Tomatillo!Q2 -> 92709.664 | J5: 60149 | K5: =+G5-I5+J5 -> 292545.9
D6: roma | E6: =+Roma!O2 -> 864923.07 | F6: =+'Estado de Cuenta R'!O38 -> 702245 | G6: =+E6-F6 -> 162678.07 | I6: =+Roma!Q2 -> 86492.307 | J6: 11968 | K6: =+G6-I6+J6 -> 88153.763
D7: morron | E7: =+Morrón!O2 -> 8380 | F7: =+'Estado de Cuenta M'!O38 -> 5980 | G7: =+E7-F7 -> 2400 | I7: =+Morrón!Q2 -> 838 | J7: 0 | K7: =+G7-I7+J7 -> 1562
E9: =SUM(E5:E8) -> 1930241.6 | F9: =SUM(F5:F8) -> 1440057 | G9: =SUM(G5:G8) -> 490184.63 | I9: =SUM(I5:I8) -> 180039.97 | J9: =SUM(J5:J8) -> 72117 | K9: =+G9-I9+J9 -> 382261.66
I11: =+I9-J9 -> 107922.97
I12: comision cxp
